üî¨ SFT vs GRPO MODEL COMPARISON
==================================================

üìä Testing: SFT Model (Working)
----------------------------------------
‚ùå Evaluation failed: Traceback (most recent call last):
  File "/home/amitjain/anaconda3/envs/unsloth_env/lib/python3.11/site-packages/peft/config.py", line 260, in _get_peft_type
    config_file = hf_hub_download(
                  ^^^^^^^^^^^^^^^^
  File "/home/amitjain/anaconda3/envs/unsloth_env/lib/python3.11/site-packages/huggingface_hub/utils/_validators.py", line 106, in _inner_fn
    validate_repo_id(arg_value)
  File "/home/amitjain/anaconda3/envs/unsloth_env/lib/python3.11/site-packages/huggingface_hub/utils/_validators.py", line 154, in validate_repo_id
    raise HFValidationError(
huggingface_hub.errors.HFValidationError: Repo id must be in the form 'repo_name' or 'namespace/repo_name': 'models/working_notebook/sft_model'. Use `repo_type` argument if needed.

During handling of the above exception, another exception occurred:

Traceback (most recent call last):
  File "/orcd/home/002/amitjain/project/Unsloth/llm_reasoning_control_refactored/scripts/evaluate_model.py", line 308, in <module>
    main()
  File "/orcd/home/002/amitjain/project/Unsloth/llm_reasoning_control_refactored/scripts/evaluate_model.py", line 114, in main
    model, tokenizer, lora_request = load_model_from_path(args.model_path)
                                     ^^^^^^^^^^^^^^^^^^^^^^^^^^^^^^^^^^^^^
  File "/orcd/home/002/amitjain/project/Unsloth/llm_reasoning_control_refactored/core/model_manager.py", line 398, in load_model_from_path
    model = PeftModel.from_pretrained(base_model, model_path)
            ^^^^^^^^^^^^^^^^^^^^^^^^^^^^^^^^^^^^^^^^^^^^^^^^^
  File "/home/amitjain/anaconda3/envs/unsloth_env/lib/python3.11/site-packages/peft/peft_model.py", line 439, in from_pretrained
    PeftConfig._get_peft_type(
  File "/home/amitjain/anaconda3/envs/unsloth_env/lib/python3.11/site-packages/peft/config.py", line 266, in _get_peft_type
    raise ValueError(f"Can't find '{CONFIG_NAME}' at '{model_id}'")
ValueError: Can't find 'adapter_config.json' at 'models/working_notebook/sft_model'


üìä Testing: GRPO Model (New)
----------------------------------------
‚úÖ Success rate: 100.0%
‚úÖ Mean performance: 0.524
‚úÖ Mean final error: 0.375

üèÜ COMPARISON RESULTS
==================================================
‚ùå Insufficient successful evaluations for comparison
   SFT Model (Working): Traceback (most recent call last):
  File "/home/amitjain/anaconda3/envs/unsloth_env/lib/python3.11/site-packages/peft/config.py", line 260, in _get_peft_type
    config_file = hf_hub_download(
                  ^^^^^^^^^^^^^^^^
  File "/home/amitjain/anaconda3/envs/unsloth_env/lib/python3.11/site-packages/huggingface_hub/utils/_validators.py", line 106, in _inner_fn
    validate_repo_id(arg_value)
  File "/home/amitjain/anaconda3/envs/unsloth_env/lib/python3.11/site-packages/huggingface_hub/utils/_validators.py", line 154, in validate_repo_id
    raise HFValidationError(
huggingface_hub.errors.HFValidationError: Repo id must be in the form 'repo_name' or 'namespace/repo_name': 'models/working_notebook/sft_model'. Use `repo_type` argument if needed.

During handling of the above exception, another exception occurred:

Traceback (most recent call last):
  File "/orcd/home/002/amitjain/project/Unsloth/llm_reasoning_control_refactored/scripts/evaluate_model.py", line 308, in <module>
    main()
  File "/orcd/home/002/amitjain/project/Unsloth/llm_reasoning_control_refactored/scripts/evaluate_model.py", line 114, in main
    model, tokenizer, lora_request = load_model_from_path(args.model_path)
                                     ^^^^^^^^^^^^^^^^^^^^^^^^^^^^^^^^^^^^^
  File "/orcd/home/002/amitjain/project/Unsloth/llm_reasoning_control_refactored/core/model_manager.py", line 398, in load_model_from_path
    model = PeftModel.from_pretrained(base_model, model_path)
            ^^^^^^^^^^^^^^^^^^^^^^^^^^^^^^^^^^^^^^^^^^^^^^^^^
  File "/home/amitjain/anaconda3/envs/unsloth_env/lib/python3.11/site-packages/peft/peft_model.py", line 439, in from_pretrained
    PeftConfig._get_peft_type(
  File "/home/amitjain/anaconda3/envs/unsloth_env/lib/python3.11/site-packages/peft/config.py", line 266, in _get_peft_type
    raise ValueError(f"Can't find '{CONFIG_NAME}' at '{model_id}'")
ValueError: Can't find 'adapter_config.json' at 'models/working_notebook/sft_model'


‚úÖ Comparison completed!
